Workbook

Sheet Sheet2
A3: Columns | B3: Count of Age | C3: Count of BusID | D3: Total Transactions | E3: Average Age | H3: Month | I3: Total riders
A4: 0-19 | B4: 8 | C4: 16 | D4: 16 | E4: 17.625 | H4: Jan | I4: 933
A5: 20-29 | B5: 13 | C5: 26 | D5: 26 | E5: 24.846154 | H5: Dec | I5: 5654
A6: 30-39 | B6: 22 | C6: 44 | D6: 44 | E6: 34.136364
A7: 40-49 | B7: 19 | C7: 38 | D7: 38 | E7: 43.578947
A8: 50-59 | B8: 21 | C8: 42 | D8: 42 | E8: 53.761905
A9: 60+ | B9: 17 | C9: 34 | D9: 34 | E9: 64.529412
A12: Count of Age | B12: Count of Occupation | C12: Average Age | E12: Time Group | F12: Total riders
A13: 100 | B13: 100 | C13: 42.69 | E13: 03:00 PM - 06:00 PM | F13: 884
E14: 06:00 PM - 09:00 PM | F14: 968
E15: 06:00 AM - 09:00 AM | F15: 973
A16: Total riders | B16: Avg rider per trip | E16: 09:00 PM - 12:00 AM | F16: 1147
A17: 6587 | B17: 32.935 | E17: 12:00 PM - 03:00 PM | F17: 1257
E18: 09:00 AM - 12:00 PM | F18: 1358
A19: Busiest route
A20: Columns | B20: Total Passengers | E20: Peak hr of operation
A21: East-West Express | B21: 1322 | E21: Time | F21: Total riders
E22: 8:57 PM | F22: 80
A23: Least Busy route
A24: Columns | B24: Total Passengers | E24: off peak hr of operation
A25: South Line | B25: 185 | E25: Time | F25: Total riders
E26: 7:50 PM | F26: 15
A27: Year | B27: Total riders
A28: 2023 | B28: 5654
A29: 2024 | B29: 933 | E29: Time | F29: Total riders | G29: Average
E30: Sun | F30: 1185 | G30: =AVERAGE($F$30:$F$36) -> 941
A31: Year | B31: Total riders | E31: Mon | F31: 1085 | G31: =AVERAGE($F$30:$F$36) -> 941
A32: 2023 | E32: Tue | F32: 983 | G32: =AVERAGE($F$30:$F$36) -> 941
A33: 2024 | B33: -0.83498408 | E33: Wed | F33: 887 | G33: =AVERAGE($F$30:$F$36) -> 941
E34: Thu | F34: 889 | G34: =AVERAGE($F$30:$F$36) -> 941
E35: Fri | F35: 762 | G35: =AVERAGE($F$30:$F$36) -> 941
A36: YoY Pct change | B36: Indicator | C36: Caption: | E36: Sat | F36: 796 | G36: =AVERAGE($F$30:$F$36) -> 941
A37: =GETPIVOTDATA("[Measures].[Sum of NumberOfRiders]",$A$31,"[Dim_DateTable].[Year]","[Dim_DateTable].[Year].&[2024]") -> -0.83498408 | B37: =IF(A37<0,A40,A39) -> ▼ | C37: =IF(A37<0,"YoY change suggests room for improvement","We are doing well on the current year") -> YoY change suggests room for improvement
A39: ▲
A40: ▼
A42: Day | B42: riders | C42: average | D42: above average | F42: Caption:
A43: Sun | B43: 1185 | C43: =AVERAGE($B$43:$B$49) -> 941 | D43: =IF(B43>C43,B43,"") -> 1185 | F43: ="Focus on highlighted weekdays: They exceeded the "&C43&" passengers average and account for "&TEXT(F46, "0.0%")&" of the Total Passengers" -> Focus on highlighted weekdays: They exceeded the 941 passengers average and account for 49.4% of the Total Passengers
A44: Mon | B44: 1085 | C44: =AVERAGE($B$43:$B$49) -> 941 | D44: =IF(B44>C44,B44,"") -> 1085
A45: Tue | B45: 983 | C45: =AVERAGE($B$43:$B$49) -> 941 | D45: =IF(B45>C45,B45,"") -> 983 | F45: Above average Percentage
A46: Wed | B46: 887 | C46: =AVERAGE($B$43:$B$49) -> 941 | D46: =IF(B46>C46,B46,"") | F46: =SUM(D43:D45)/SUM(B43:B49) -> 0.49385153
...

Sheet Dashboard

Sheet Sheet1
B2: total passengers | D2: avg rider per trip
B3: =GETPIVOTDATA("[Measures].[Sum of NumberOfRiders]",Sheet2!$A$16) -> 6587 | D3: =GETPIVOTDATA("[Measures].[Avg rider per bus]",Sheet2!$A$16) -> 32.935 | G3: =Sheet2!E22 -> 8:57 PM | I3: =Sheet2!E26 -> 7:50 PM | K3: =Sheet2!A37 -> -0.83498408 | M3: =Sheet2!B37 -> ▼
